Workbook

Sheet 📖 Instrucciones
A1: CÓMO LLENAR ESTA PLANTILLA
B4: Esta plantilla es relacional: toda la información se carga una sola vez en los tres
B5: directorios, y la hoja de Prácticas se arma eligiendo de listas desplegables.
B7: Paso 1 — Hoja «Estudiantes»
B8: Registra a cada estudiante con su cédula, nombre, correo, carrera y celular, y también
B9: el tipo de práctica, el nivel académico, las horas y el período que le corresponden.
B11: Paso 2 — Hoja «Empresas»
B12: Registra cada empresa receptora con su contacto o representante (companyContactName), el cargo
B13: de esa persona (companyPosition), su correo y su teléfono. Este contacto y su cargo son los que
B14: aparecen como destinatario en los oficios (Solicitud de Prácticas y Designación).
B16: Paso 3 — Hoja «Tutores Académicos»
B17: Registra a los docentes que harán el seguimiento. La última columna cuenta sola cuántos
B18: estudiantes le tocan a cada uno.
... B29: de guardar nada.

Sheet 👥 Estudiantes
A1: DIRECTORIO DE ESTUDIANTES · aquí va todo lo del estudiante y de su práctica
A2: N° | B2: Cédula | C2: Apellidos y Nombres | D2: Correo Institucional | E2: Carrera | F2: Celular | G2: Tipo de Práctica | H2: Nivel Académico | I2: Horas | J2: Periodo
A3: 1 | B3: 1315900520 | C3: Aguilar Aguilera Isabella Verónica | D3: e1315900520@live.uleam.edu.ec | E3: Tecnologías de la Información | F3: 0926492538 | G3: Prácticas Laborales II | H3: Octavo Nivel | I3: 120 | J3: 2024-1
A4: 2 | B4: 1315900538 | C4: Alava Moreira Luis Alejandro | D4: e1315900538@live.uleam.edu.ec | E4: Tecnologías de la Información | F4: 0979224043 | G4: Prácticas Laborales I | H4: Séptimo Nivel | I4: 192 | J4: 2024-1
A5: 3 | B5: 1315900546 | C5: Alcivar Franco Nancy Paola | D5: e1315900546@live.uleam.edu.ec | E5: Tecnologías de la Información | F5: 0961953426 | G5: Prácticas Laborales I | H5: Séptimo Nivel | I5: 180 | J5: 2024-1
A6: 4 | B6: 1315900553 | C6: Alcívar Córdova Pedro Luis | D6: e1315900553@live.uleam.edu.ec | E6: Tecnologías de la Información | F6: 0914781158 | G6: Prácticas Laborales I | H6: Séptimo Nivel | I6: 192 | J6: 2024-1
A7: 5 | B7: 1315900561 | C7: Alonzo Pico Devis Yonaikel | D7: e1315900561@live.uleam.edu.ec | E7: Tecnologías de la Información | F7: 0991742507 | G7: Prácticas Laborales II | H7: Octavo Nivel | I7: 120 | J7: 2024-1
A8: 6 | B8: 1315900579 | C8: Alvarado Chavez Jimmy Santiago | D8: e1315900579@live.uleam.edu.ec | E8: Tecnologías de la Información | F8: 0981077349 | G8: Prácticas Laborales I | H8: Séptimo Nivel | I8: 180 | J8: 2024-1
A9: 7 | B9: 1315900587 | C9: Anchundia Anchundia Liliana Margarita | D9: e1315900587@live.uleam.edu.ec | E9: Tecnologías de la Información | F9: 0958709236 | G9: Prácticas Laborales I | H9: Séptimo Nivel | I9: 192 | J9: 2024-1
A10: 8 | B10: 1315900595 | C10: Anchundia Chavez Belinda Yusmeli | D10: e1315900595@live.uleam.edu.ec | E10: Tecnologías de la Información | F10: 0918387442 | G10: Prácticas Laborales I | H10: Séptimo Nivel | I10: 192 | J10: 2024-1
A11: 9 | B11: 1315900603 | C11: Anchundia Parraga Diego Ariel | D11: e1315900603@live.uleam.edu.ec | E11: Tecnologías de la Información | F11: 0997713211 | G11: Prácticas Laborales I | H11: Séptimo Nivel | I11: 192 | J11: 2024-1
A12: 10 | B12: 1315900611 | C12: Andrade Mera Maholy Abigail | D12: e1315900611@live.uleam.edu.ec | E12: Tecnologías de la Información | F12: 0928113920 | G12: Prácticas Laborales II | H12: Octavo Nivel | I12: 120 | J12: 2024-1
A13: 11 | B13: 1315900629 | C13: Anzules Reyes Luis Manuel | D13: e1315900629@live.uleam.edu.ec | E13: Tecnologías de la Información | F13: 0941064188 | G13: Prácticas Laborales I | H13: Séptimo Nivel | I13: 180 | J13: 2024-1
A14: 12 | B14: 1315900637 | C14: Arteaga Santana Bryan Steven | D14: e1315900637@live.uleam.edu.ec | E14: Tecnologías de la Información | F14: 0983439218 | G14: Prácticas Laborales I | H14: Séptimo Nivel | I14: 192 | J14: 2024-1
... A139: 137 | B139: 1315901882 | C139: Zamora Piguave Miguel Ignacio | D139: e1315901882@live.uleam.edu.ec | E139: Tecnologías de la Información | F139: 0995588056 | G139: Prácticas Laborales I | H139: Séptimo Nivel | I139: 192 | J139: 2024-1

Sheet 🏢 Empresas
A1: DIRECTORIO DE EMPRESAS RECEPTORAS
A2: N° | B2: Nombre Empresa | C2: Contacto / Destinatario de la Empresa | D2: Cargo del Contacto / Destinatario | E2: Email | F2: Teléfono
A3: 1 | B3: ADMINISTRADOR DE FCVT | C3: Ing. Mike Machuca | D3: Administrador de la Facultad de Ciencias de la Vida y Tecnología | E3: mike.machuca@uleam.edu.ec | F3: 993419854
A4: 2 | B4: ALTURA S.A. | C4: Ing. Byron Macías Alcívar | D4: Gerente General | E4: gerencia@altura.com.ec | F4: 0960048753
A5: 3 | B5: ANDICOM | C5: Sra. Jessica Anchundia | D5: Gerente Andicom | E5: jessica.anchundiaa@gmail.com | F5: 982485536
A6: 4 | B6: ASETECSA S.A. | C6: Ing. Martha Villamil | D6: Gerente General | E6: nino1511@hotmail.com | F6: 997480006
A7: 5 | B7: ATUKHOSTING | C7: Ing. Fabián Zambrano Loor | D7: Jefe de Tecnologías de la Información | E7: soporte@atukhosting.com | F7: 0960124591
A8: 6 | B8: AUTORIDAD PORTUARIA DE MANTA | C8: Lcda. Elena Bailón Santana | D8: Jefe de Sistemas | E8: sistemas@autoridadportuaria.gob.ec | F8: 052610867
A9: 7 | B9: AYUDANTIA DE CATEDRA (ALGEBRA LINEAL) | C9: Ing. Mero Henry | D9: Docente ULEAM | E9: henry.mero@uleam.edu.ec | F9: 989170708
A10: 8 | B10: AYUDANTIA DE CATEDRA (FUNDAMENTOS DE PROGRAMACIÓN) | C10: Ing. Armando Franco Pico | D10: Docente ULEAM | E10: armando.franco@uleam.edu.ec | F10: 984579272
A11: 9 | B11: AYUDANTIA DE CATEDRA (ING. SOFTWARE I) | C11: Ing. William Delgado | D11: Docente ULEAM | E11: william.delgado@uleam.edu.ec | F11: 980778865
A12: 10 | B12: AYUDANTIA DE CATEDRA (ING. WILLIAM ZAMORA) | C12: Sr. Pico Santana Milton Ramiro | D12: Gerente General | E12: miltonsantana78@hotmail.com | F12: 984142004
A13: 11 | B13: BENEMÉRITO CUERPO DE BOMBEROS DE MANTA | C13: Lcda. Mariana Vélez Cedeño | D13: Jefe de Sistemas | E13: sistemas@benemeritocuerpo.gob.ec | F13: 052674219
A14: 12 | B14: BIENESTAR UNIVERSITARIO | C14: Ing. Harol Ormaza | D14: Director Bienestar Universitario | E14: douglas.anzules@uleam.edu.ec | F14: 985149072
... A74: 72 | B74: ZGAMES | C74: Ing. Elizabeth Rodríguez | D74: Product Manager | E74: oficaldecumplimiento@zgameslatam.com | F74: 994283082

Sheet 👨‍🏫 Tutores Académicos
A1: TUTORES ACADÉMICOS
A2: N° | B2: Nombre Completo con Título | C2: N° Estudiantes Asignados
A3: 1 | B3: Ing. Juan Carlos Sendón Varela. Mg. | C3: =IF($B3="","",COUNTIF('📋 Prácticas'!$K$3:$K$200,$B3))
A4: 2 | B4: Ing. José Jacinto Reyes Cárdenas. Mg. | C4: =IF($B4="","",COUNTIF('📋 Prácticas'!$K$3:$K$200,$B4))
A5: 3 | B5: Ing. Carlos Manosalvas García. Mg. | C5: =IF($B5="","",COUNTIF('📋 Prácticas'!$K$3:$K$200,$B5))
A6: 4 | B6: Ing. Fabricio Javier Rivadeneira Zambrano. Mg. | C6: =IF($B6="","",COUNTIF('📋 Prácticas'!$K$3:$K$200,$B6))
A7: 5 | B7: Ing. Luis Jacinto Mendoza Cuzme. Mg. | C7: =IF($B7="","",COUNTIF('📋 Prácticas'!$K$3:$K$200,$B7))
A8: 6 | B8: Ing. Walter Colón García Vélez. Mg. | C8: =IF($B8="","",COUNTIF('📋 Prácticas'!$K$3:$K$200,$B8))
A9: 7 | B9: Ing. Robert Wilfrido Moreira Centeno, Mg | C9: =IF($B9="","",COUNTIF('📋 Prácticas'!$K$3:$K$200,$B9))
A10: 8 | B10: Ing. Hiraida Monserrate Santana Cedeño. Mg. | C10: =IF($B10="","",COUNTIF('📋 Prácticas'!$K$3:$K$200,$B10))
A11: 9 | B11: Ing. Willian Jesus Zamora Mero. PhD. | C11: =IF($B11="","",COUNTIF('📋 Prácticas'!$K$3:$K$200,$B11))
A12: 10 | B12: Ing. Luigi Fabian Pihuave Calderon. Mg. | C12: =IF($B12="","",COUNTIF('📋 Prácticas'!$K$3:$K$200,$B12))
A13: 11 | B13: Ing. Marco Wellington Ayovi Ramirez. PhD. | C13: =IF($B13="","",COUNTIF('📋 Prácticas'!$K$3:$K$200,$B13))
A14: 12 | B14: Ing. Walter Daniel Parraga Andrade. Mg. | C14: =IF($B14="","",COUNTIF('📋 Prácticas'!$K$3:$K$200,$B14))

Sheet 📋 Prácticas
A1: ASIGNACIÓN DE PRÁCTICAS · elija estudiante, empresa y tutor; el resto se completa solo
A2: N° | B2: Cédula | C2: Apellidos y Nombres | D2: Correo Institucional | E2: Carrera | F2: Empresa Receptora | G2: Contacto / Destinatario de la Empresa | H2: Cargo del Contacto / Destinatario | I2: Email Empresa | J2: Teléfono Empresa | K2: Tutor Académico | L2: Tipo de Práctica | M2: Nivel Académico | N2: Horas | O2: Periodo | P2: Área de Desempeño
A3: =IF($C3="","",ROW()-2) | B3: =IFERROR(INDEX('👥 Estudiantes'!$B$3:$B$200,MATCH($C3,'👥 Estudiantes'!$C$3:$C$200,0)),"") | C3: Aguilar Aguilera Isabella Verónica | D3: =IFERROR(INDEX('👥 Estudiantes'!$D$3:$D$200,MATCH($C3,'👥 Estudiantes'!$C$3:$C$200,0)),"") | E3: =IFERROR(INDEX('👥 Estudiantes'!$E$3:$E$200,MATCH($C3,'👥 Estudiantes'!$C$3:$C$200,0)),"") | F3: COLEGIO DE BIOLOGOS | G3: =IFERROR(INDEX('🏢 Empresas'!$C$3:$C$200,MATCH($F3,'🏢 Empresas'!$B$3:$B$200,0)),"") | H3: =IFERROR(INDEX('🏢 Empresas'!$D$3:$D$200,MATCH($F3,'🏢 Empresas'!$B$3:$B$200,0)),"") | I3: =IFERROR(INDEX('🏢 Empresas'!$E$3:$E$200,MATCH($F3,'🏢 Empresas'!$B$3:$B$200,0)),"") | J3: =IFERROR(INDEX('🏢 Empresas'!$F$3:$F$200,MATCH($F3,'🏢 Empresas'!$B$3:$B$200,0)),"") | K3: Ing. José Jacinto Reyes Cárdenas. Mg. | L3: =IFERROR(INDEX('👥 Estudiantes'!$G$3:$G$200,MATCH($C3,'👥 Estudiantes'!$C$3:$C$200,0)),"") | M3: =IFERROR(INDEX('👥 Estudiantes'!$H$3:$H$200,MATCH($C3,'👥 Estudiantes'!$C$3:$C$200,0)),"") | N3: =IFERROR(INDEX('👥 Estudiantes'!$I$3:$I$200,MATCH($C3,'👥 Estudiantes'!$C$3:$C$200,0)),"") | O3: =IFERROR(INDEX('👥 Estudiantes'!$J$3:$J$200,MATCH($C3,'👥 Estudiantes'!$C$3:$C$200,0)),"") | P3: Soporte Técnico
A4: =IF($C4="","",ROW()-2) | B4: =IFERROR(INDEX('👥 Estudiantes'!$B$3:$B$200,MATCH($C4,'👥 Estudiantes'!$C$3:$C$200,0)),"") | C4: Alava Moreira Luis Alejandro | D4: =IFERROR(INDEX('👥 Estudiantes'!$D$3:$D$200,MATCH($C4,'👥 Estudiantes'!$C$3:$C$200,0)),"") | E4: =IFERROR(INDEX('👥 Estudiantes'!$E$3:$E$200,MATCH($C4,'👥 Estudiantes'!$C$3:$C$200,0)),"") | F4: EPAM | G4: =IFERROR(INDEX('🏢 Empresas'!$C$3:$C$200,MATCH($F4,'🏢 Empresas'!$B$3:$B$200,0)),"") | H4: =IFERROR(INDEX('🏢 Empresas'!$D$3:$D$200,MATCH($F4,'🏢 Empresas'!$B$3:$B$200,0)),"") | I4: =IFERROR(INDEX('🏢 Empresas'!$E$3:$E$200,MATCH($F4,'🏢 Empresas'!$B$3:$B$200,0)),"") | J4: =IFERROR(INDEX('🏢 Empresas'!$F$3:$F$200,MATCH($F4,'🏢 Empresas'!$B$3:$B$200,0)),"") | K4: Ing. Willian Jesus Zamora Mero. PhD. | L4: =IFERROR(INDEX('👥 Estudiantes'!$G$3:$G$200,MATCH($C4,'👥 Estudiantes'!$C$3:$C$200,0)),"") | M4: =IFERROR(INDEX('👥 Estudiantes'!$H$3:$H$200,MATCH($C4,'👥 Estudiantes'!$C$3:$C$200,0)),"") | N4: =IFERROR(INDEX('👥 Estudiantes'!$I$3:$I$200,MATCH($C4,'👥 Estudiantes'!$C$3:$C$200,0)),"") | O4: =IFERROR(INDEX('👥 Estudiantes'!$J$3:$J$200,MATCH($C4,'👥 Estudiantes'!$C$3:$C$200,0)),"") | P4: Sistemas
A5: =IF($C5="","",ROW()-2) | B5: =IFERROR(INDEX('👥 Estudiantes'!$B$3:$B$200,MATCH($C5,'👥 Estudiantes'!$C$3:$C$200,0)),"") | C5: Alcivar Franco Nancy Paola | D5: =IFERROR(INDEX('👥 Estudiantes'!$D$3:$D$200,MATCH($C5,'👥 Estudiantes'!$C$3:$C$200,0)),"") | E5: =IFERROR(INDEX('👥 Estudiantes'!$E$3:$E$200,MATCH($C5,'👥 Estudiantes'!$C$3:$C$200,0)),"") | F5: UNIDAD EDUCATIVA ISRAEL | G5: =IFERROR(INDEX('🏢 Empresas'!$C$3:$C$200,MATCH($F5,'🏢 Empresas'!$B$3:$B$200,0)),"") | H5: =IFERROR(INDEX('🏢 Empresas'!$D$3:$D$200,MATCH($F5,'🏢 Empresas'!$B$3:$B$200,0)),"") | I5: =IFERROR(INDEX('🏢 Empresas'!$E$3:$E$200,MATCH($F5,'🏢 Empresas'!$B$3:$B$200,0)),"") | J5: =IFERROR(INDEX('🏢 Empresas'!$F$3:$F$200,MATCH($F5,'🏢 Empresas'!$B$3:$B$200,0)),"") | K5: Ing. Walter Colón García Vélez. Mg. | L5: =IFERROR(INDEX('👥 Estudiantes'!$G$3:$G$200,MATCH($C5,'👥 Estudiantes'!$C$3:$C$200,0)),"") | M5: =IFERROR(INDEX('👥 Estudiantes'!$H$3:$H$200,MATCH($C5,'👥 Estudiantes'!$C$3:$C$200,0)),"") | N5: =IFERROR(INDEX('👥 Estudiantes'!$I$3:$I$200,MATCH($C5,'👥 Estudiantes'!$C$3:$C$200,0)),"") | O5: =IFERROR(INDEX('👥 Estudiantes'!$J$3:$J$200,MATCH($C5,'👥 Estudiantes'!$C$3:$C$200,0)),"") | P5: Soporte Técnico
A6: =IF($C6="","",ROW()-2) | B6: =IFERROR(INDEX('👥 Estudiantes'!$B$3:$B$200,MATCH($C6,'👥 Estudiantes'!$C$3:$C$200,0)),"") | C6: Alcívar Córdova Pedro Luis | D6: =IFERROR(INDEX('👥 Estudiantes'!$D$3:$D$200,MATCH($C6,'👥 Estudiantes'!$C$3:$C$200,0)),"") | E6: =IFERROR(INDEX('👥 Estudiantes'!$E$3:$E$200,MATCH($C6,'👥 Estudiantes'!$C$3:$C$200,0)),"") | F6: INSTITUTO DE NEUROCIENCIAS | G6: =IFERROR(INDEX('🏢 Empresas'!$C$3:$C$200,MATCH($F6,'🏢 Empresas'!$B$3:$B$200,0)),"") | H6: =IFERROR(INDEX('🏢 Empresas'!$D$3:$D$200,MATCH($F6,'🏢 Empresas'!$B$3:$B$200,0)),"") | I6: =IFERROR(INDEX('🏢 Empresas'!$E$3:$E$200,MATCH($F6,'🏢 Empresas'!$B$3:$B$200,0)),"") | J6: =IFERROR(INDEX('🏢 Empresas'!$F$3:$F$200,MATCH($F6,'🏢 Empresas'!$B$3:$B$200,0)),"") | K6: Ing. Walter Daniel Parraga Andrade. Mg. | L6: =IFERROR(INDEX('👥 Estudiantes'!$G$3:$G$200,MATCH($C6,'👥 Estudiantes'!$C$3:$C$200,0)),"") | M6: =IFERROR(INDEX('👥 Estudiantes'!$H$3:$H$200,MATCH($C6,'👥 Estudiantes'!$C$3:$C$200,0)),"") | N6: =IFERROR(INDEX('👥 Estudiantes'!$I$3:$I$200,MATCH($C6,'👥 Estudiantes'!$C$3:$C$200,0)),"") | O6: =IFERROR(INDEX('👥 Estudiantes'!$J$3:$J$200,MATCH($C6,'👥 Estudiantes'!$C$3:$C$200,0)),"") | P6: Soporte Técnico
A7: =IF($C7="","",ROW()-2) | B7: =IFERROR(INDEX('👥 Estudiantes'!$B$3:$B$200,MATCH($C7,'👥 Estudiantes'!$C$3:$C$200,0)),"") | C7: Alonzo Pico Devis Yonaikel | D7: =IFERROR(INDEX('👥 Estudiantes'!$D$3:$D$200,MATCH($C7,'👥 Estudiantes'!$C$3:$C$200,0)),"") | E7: =IFERROR(INDEX('👥 Estudiantes'!$E$3:$E$200,MATCH($C7,'👥 Estudiantes'!$C$3:$C$200,0)),"") | F7: EPESPO | G7: =IFERROR(INDEX('🏢 Empresas'!$C$3:$C$200,MATCH($F7,'🏢 Empresas'!$B$3:$B$200,0)),"") | H7: =IFERROR(INDEX('🏢 Empresas'!$D$3:$D$200,MATCH($F7,'🏢 Empresas'!$B$3:$B$200,0)),"") | I7: =IFERROR(INDEX('🏢 Empresas'!$E$3:$E$200,MATCH($F7,'🏢 Empresas'!$B$3:$B$200,0)),"") | J7: =IFERROR(INDEX('🏢 Empresas'!$F$3:$F$200,MATCH($F7,'🏢 Empresas'!$B$3:$B$200,0)),"") | K7: Ing. José Jacinto Reyes Cárdenas. Mg. | L7: =IFERROR(INDEX('👥 Estudiantes'!$G$3:$G$200,MATCH($C7,'👥 Estudiantes'!$C$3:$C$200,0)),"") | M7: =IFERROR(INDEX('👥 Estudiantes'!$H$3:$H$200,MATCH($C7,'👥 Estudiantes'!$C$3:$C$200,0)),"") | N7: =IFERROR(INDEX('👥 Estudiantes'!$I$3:$I$200,MATCH($C7,'👥 Estudiantes'!$C$3:$C$200,0)),"") | O7: =IFERROR(INDEX('👥 Estudiantes'!$J$3:$J$200,MATCH($C7,'👥 Estudiantes'!$C$3:$C$200,0)),"") | P7: TI
A8: =IF($C8="","",ROW()-2) | B8: =IFERROR(INDEX('👥 Estudiantes'!$B$3:$B$200,MATCH($C8,'👥 Estudiantes'!$C$3:$C$200,0)),"") | C8: Alvarado Chavez Jimmy Santiago | D8: =IFERROR(INDEX('👥 Estudiantes'!$D$3:$D$200,MATCH($C8,'👥 Estudiantes'!$C$3:$C$200,0)),"") | E8: =IFERROR(INDEX('👥 Estudiantes'!$E$3:$E$200,MATCH($C8,'👥 Estudiantes'!$C$3:$C$200,0)),"") | F8: FISHCORP | G8: =IFERROR(INDEX('🏢 Empresas'!$C$3:$C$200,MATCH($F8,'🏢 Empresas'!$B$3:$B$200,0)),"") | H8: =IFERROR(INDEX('🏢 Empresas'!$D$3:$D$200,MATCH($F8,'🏢 Empresas'!$B$3:$B$200,0)),"") | I8: =IFERROR(INDEX('🏢 Empresas'!$E$3:$E$200,MATCH($F8,'🏢 Empresas'!$B$3:$B$200,0)),"") | J8: =IFERROR(INDEX('🏢 Empresas'!$F$3:$F$200,MATCH($F8,'🏢 Empresas'!$B$3:$B$200,0)),"") | K8: Ing. Luis Jacinto Mendoza Cuzme. Mg. | L8: =IFERROR(INDEX('👥 Estudiantes'!$G$3:$G$200,MATCH($C8,'👥 Estudiantes'!$C$3:$C$200,0)),"") | M8: =IFERROR(INDEX('👥 Estudiantes'!$H$3:$H$200,MATCH($C8,'👥 Estudiantes'!$C$3:$C$200,0)),"") | N8: =IFERROR(INDEX('👥 Estudiantes'!$I$3:$I$200,MATCH($C8,'👥 Estudiantes'!$C$3:$C$200,0)),"") | O8: =IFERROR(INDEX('👥 Estudiantes'!$J$3:$J$200,MATCH($C8,'👥 Estudiantes'!$C$3:$C$200,0)),"") | P8: Redes y Comunicaciones
A9: =IF($C9="","",ROW()-2) | B9: =IFERROR(INDEX('👥 Estudiantes'!$B$3:$B$200,MATCH($C9,'👥 Estudiantes'!$C$3:$C$200,0)),"") | C9: Anchundia Anchundia Liliana Margarita | D9: =IFERROR(INDEX('👥 Estudiantes'!$D$3:$D$200,MATCH($C9,'👥 Estudiantes'!$C$3:$C$200,0)),"") | E9: =IFERROR(INDEX('👥 Estudiantes'!$E$3:$E$200,MATCH($C9,'👥 Estudiantes'!$C$3:$C$200,0)),"") | F9: HOSPITAL RODRIGUEZ ZAMBRANO | G9: =IFERROR(INDEX('🏢 Empresas'!$C$3:$C$200,MATCH($F9,'🏢 Empresas'!$B$3:$B$200,0)),"") | H9: =IFERROR(INDEX('🏢 Empresas'!$D$3:$D$200,MATCH($F9,'🏢 Empresas'!$B$3:$B$200,0)),"") | I9: =IFERROR(INDEX('🏢 Empresas'!$E$3:$E$200,MATCH($F9,'🏢 Empresas'!$B$3:$B$200,0)),"") | J9: =IFERROR(INDEX('🏢 Empresas'!$F$3:$F$200,MATCH($F9,'🏢 Empresas'!$B$3:$B$200,0)),"") | K9: Ing. Robert Wilfrido Moreira Centeno, Mg | L9: =IFERROR(INDEX('👥 Estudiantes'!$G$3:$G$200,MATCH($C9,'👥 Estudiantes'!$C$3:$C$200,0)),"") | M9: =IFERROR(INDEX('👥 Estudiantes'!$H$3:$H$200,MATCH($C9,'👥 Estudiantes'!$C$3:$C$200,0)),"") | N9: =IFERROR(INDEX('👥 Estudiantes'!$I$3:$I$200,MATCH($C9,'👥 Estudiantes'!$C$3:$C$200,0)),"") | O9: =IFERROR(INDEX('👥 Estudiantes'!$J$3:$J$200,MATCH($C9,'👥 Estudiantes'!$C$3:$C$200,0)),"") | P9: Redes y Comunicaciones
A10: =IF($C10="","",ROW()-2) | B10: =IFERROR(INDEX('👥 Estudiantes'!$B$3:$B$200,MATCH($C10,'👥 Estudiantes'!$C$3:$C$200,0)),"") | C10: Anchundia Chavez Belinda Yusmeli | D10: =IFERROR(INDEX('👥 Estudiantes'!$D$3:$D$200,MATCH($C10,'👥 Estudiantes'!$C$3:$C$200,0)),"") | E10: =IFERROR(INDEX('👥 Estudiantes'!$E$3:$E$200,MATCH($C10,'👥 Estudiantes'!$C$3:$C$200,0)),"") | F10: ULEAM-EP | G10: =IFERROR(INDEX('🏢 Empresas'!$C$3:$C$200,MATCH($F10,'🏢 Empresas'!$B$3:$B$200,0)),"") | H10: =IFERROR(INDEX('🏢 Empresas'!$D$3:$D$200,MATCH($F10,'🏢 Empresas'!$B$3:$B$200,0)),"") | I10: =IFERROR(INDEX('🏢 Empresas'!$E$3:$E$200,MATCH($F10,'🏢 Empresas'!$B$3:$B$200,0)),"") | J10: =IFERROR(INDEX('🏢 Empresas'!$F$3:$F$200,MATCH($F10,'🏢 Empresas'!$B$3:$B$200,0)),"") | K10: Ing. Robert Wilfrido Moreira Centeno, Mg | L10: =IFERROR(INDEX('👥 Estudiantes'!$G$3:$G$200,MATCH($C10,'👥 Estudiantes'!$C$3:$C$200,0)),"") | M10: =IFERROR(INDEX('👥 Estudiantes'!$H$3:$H$200,MATCH($C10,'👥 Estudiantes'!$C$3:$C$200,0)),"") | N10: =IFERROR(INDEX('👥 Estudiantes'!$I$3:$I$200,MATCH($C10,'👥 Estudiantes'!$C$3:$C$200,0)),"") | O10: =IFERROR(INDEX('👥 Estudiantes'!$J$3:$J$200,MATCH($C10,'👥 Estudiantes'!$C$3:$C$200,0)),"") | P10: Desarrollo de Software
A11: =IF($C11="","",ROW()-2) | B11: =IFERROR(INDEX('👥 Estudiantes'!$B$3:$B$200,MATCH($C11,'👥 Estudiantes'!$C$3:$C$200,0)),"") | C11: Anchundia Parraga Diego Ariel | D11: =IFERROR(INDEX('👥 Estudiantes'!$D$3:$D$200,MATCH($C11,'👥 Estudiantes'!$C$3:$C$200,0)),"") | E11: =IFERROR(INDEX('👥 Estudiantes'!$E$3:$E$200,MATCH($C11,'👥 Estudiantes'!$C$3:$C$200,0)),"") | F11: HOSPITAL RODRIGUEZ ZAMBRANO | G11: =IFERROR(INDEX('🏢 Empresas'!$C$3:$C$200,MATCH($F11,'🏢 Empresas'!$B$3:$B$200,0)),"") | H11: =IFERROR(INDEX('🏢 Empresas'!$D$3:$D$200,MATCH($F11,'🏢 Empresas'!$B$3:$B$200,0)),"") | I11: =IFERROR(INDEX('🏢 Empresas'!$E$3:$E$200,MATCH($F11,'🏢 Empresas'!$B$3:$B$200,0)),"") | J11: =IFERROR(INDEX('🏢 Empresas'!$F$3:$F$200,MATCH($F11,'🏢 Empresas'!$B$3:$B$200,0)),"") | K11: Ing. Robert Wilfrido Moreira Centeno, Mg | L11: =IFERROR(INDEX('👥 Estudiantes'!$G$3:$G$200,MATCH($C11,'👥 Estudiantes'!$C$3:$C$200,0)),"") | M11: =IFERROR(INDEX('👥 Estudiantes'!$H$3:$H$200,MATCH($C11,'👥 Estudiantes'!$C$3:$C$200,0)),"") | N11: =IFERROR(INDEX('👥 Estudiantes'!$I$3:$I$200,MATCH($C11,'👥 Estudiantes'!$C$3:$C$200,0)),"") | O11: =IFERROR(INDEX('👥 Estudiantes'!$J$3:$J$200,MATCH($C11,'👥 Estudiantes'!$C$3:$C$200,0)),"") | P11: TI
A12: =IF($C12="","",ROW()-2) | B12: =IFERROR(INDEX('👥 Estudiantes'!$B$3:$B$200,MATCH($C12,'👥 Estudiantes'!$C$3:$C$200,0)),"") | C12: Andrade Mera Maholy Abigail | D12: =IFERROR(INDEX('👥 Estudiantes'!$D$3:$D$200,MATCH($C12,'👥 Estudiantes'!$C$3:$C$200,0)),"") | E12: =IFERROR(INDEX('👥 Estudiantes'!$E$3:$E$200,MATCH($C12,'👥 Estudiantes'!$C$3:$C$200,0)),"") | F12: CONSERVAS ISABEL S.A | G12: =IFERROR(INDEX('🏢 Empresas'!$C$3:$C$200,MATCH($F12,'🏢 Empresas'!$B$3:$B$200,0)),"") | H12: =IFERROR(INDEX('🏢 Empresas'!$D$3:$D$200,MATCH($F12,'🏢 Empresas'!$B$3:$B$200,0)),"") | I12: =IFERROR(INDEX('🏢 Empresas'!$E$3:$E$200,MATCH($F12,'🏢 Empresas'!$B$3:$B$200,0)),"") | J12: =IFERROR(INDEX('🏢 Empresas'!$F$3:$F$200,MATCH($F12,'🏢 Empresas'!$B$3:$B$200,0)),"") | K12: Ing. Fabricio Javier Rivadeneira Zambrano. Mg. | L12: =IFERROR(INDEX('👥 Estudiantes'!$G$3:$G$200,MATCH($C12,'👥 Estudiantes'!$C$3:$C$200,0)),"") | M12: =IFERROR(INDEX('👥 Estudiantes'!$H$3:$H$200,MATCH($C12,'👥 Estudiantes'!$C$3:$C$200,0)),"") | N12: =IFERROR(INDEX('👥 Estudiantes'!$I$3:$I$200,MATCH($C12,'👥 Estudiantes'!$C$3:$C$200,0)),"") | O12: =IFERROR(INDEX('👥 Estudiantes'!$J$3:$J$200,MATCH($C12,'👥 Estudiantes'!$C$3:$C$200,0)),"") | P12: TI
A13: =IF($C13="","",ROW()-2) | B13: =IFERROR(INDEX('👥 Estudiantes'!$B$3:$B$200,MATCH($C13,'👥 Estudiantes'!$C$3:$C$200,0)),"") | C13: Anzules Reyes Luis Manuel | D13: =IFERROR(INDEX('👥 Estudiantes'!$D$3:$D$200,MATCH($C13,'👥 Estudiantes'!$C$3:$C$200,0)),"") | E13: =IFERROR(INDEX('👥 Estudiantes'!$E$3:$E$200,MATCH($C13,'👥 Estudiantes'!$C$3:$C$200,0)),"") | F13: GAD MANTA | G13: =IFERROR(INDEX('🏢 Empresas'!$C$3:$C$200,MATCH($F13,'🏢 Empresas'!$B$3:$B$200,0)),"") | H13: =IFERROR(INDEX('🏢 Empresas'!$D$3:$D$200,MATCH($F13,'🏢 Empresas'!$B$3:$B$200,0)),"") | I13: =IFERROR(INDEX('🏢 Empresas'!$E$3:$E$200,MATCH($F13,'🏢 Empresas'!$B$3:$B$200,0)),"") | J13: =IFERROR(INDEX('🏢 Empresas'!$F$3:$F$200,MATCH($F13,'🏢 Empresas'!$B$3:$B$200,0)),"") | K13: Ing. Carlos Manosalvas García. Mg. | L13: =IFERROR(INDEX('👥 Estudiantes'!$G$3:$G$200,MATCH($C13,'👥 Estudiantes'!$C$3:$C$200,0)),"") | M13: =IFERROR(INDEX('👥 Estudiantes'!$H$3:$H$200,MATCH($C13,'👥 Estudiantes'!$C$3:$C$200,0)),"") | N13: =IFERROR(INDEX('👥 Estudiantes'!$I$3:$I$200,MATCH($C13,'👥 Estudiantes'!$C$3:$C$200,0)),"") | O13: =IFERROR(INDEX('👥 Estudiantes'!$J$3:$J$200,MATCH($C13,'👥 Estudiantes'!$C$3:$C$200,0)),"") | P13: Redes y Comunicaciones
A14: =IF($C14="","",ROW()-2) | B14: =IFERROR(INDEX('👥 Estudiantes'!$B$3:$B$200,MATCH($C14,'👥 Estudiantes'!$C$3:$C$200,0)),"") | C14: Arteaga Santana Bryan Steven | D14: =IFERROR(INDEX('👥 Estudiantes'!$D$3:$D$200,MATCH($C14,'👥 Estudiantes'!$C$3:$C$200,0)),"") | E14: =IFERROR(INDEX('👥 Estudiantes'!$E$3:$E$200,MATCH($C14,'👥 Estudiantes'!$C$3:$C$200,0)),"") | F14: PROMOPESCA | G14: =IFERROR(INDEX('🏢 Empresas'!$C$3:$C$200,MATCH($F14,'🏢 Empresas'!$B$3:$B$200,0)),"") | H14: =IFERROR(INDEX('🏢 Empresas'!$D$3:$D$200,MATCH($F14,'🏢 Empresas'!$B$3:$B$200,0)),"") | I14: =IFERROR(INDEX('🏢 Empresas'!$E$3:$E$200,MATCH($F14,'🏢 Empresas'!$B$3:$B$200,0)),"") | J14: =IFERROR(INDEX('🏢 Empresas'!$F$3:$F$200,MATCH($F14,'🏢 Empresas'!$B$3:$B$200,0)),"") | K14: Ing. Luigi Fabian Pihuave Calderon. Mg. | L14: =IFERROR(INDEX('👥 Estudiantes'!$G$3:$G$200,MATCH($C14,'👥 Estudiantes'!$C$3:$C$200,0)),"") | M14: =IFERROR(INDEX('👥 Estudiantes'!$H$3:$H$200,MATCH($C14,'👥 Estudiantes'!$C$3:$C$200,0)),"") | N14: =IFERROR(INDEX('👥 Estudiantes'!$I$3:$I$200,MATCH($C14,'👥 Estudiantes'!$C$3:$C$200,0)),"") | O14: =IFERROR(INDEX('👥 Estudiantes'!$J$3:$J$200,MATCH($C14,'👥 Estudiantes'!$C$3:$C$200,0)),"") | P14: Redes y Comunicaciones
... A70: =IF($C70="","",ROW()-2) | B70: =IFERROR(INDEX('👥 Estudiantes'!$B$3:$B$200,MATCH($C70,'👥 Estudiantes'!$C$3:$C$200,0)),"") | C70: Lorente Tello Ericka Dayana | D70: =IFERROR(INDEX('👥 Estudiantes'!$D$3:$D$200,MATCH($C70,'👥 Estudiantes'!$C$3:$C$200,0)),"") | E70: =IFERROR(INDEX('👥 Estudiantes'!$E$3:$E$200,MATCH($C70,'👥 Estudiantes'!$C$3:$C$200,0)),"") | F70: CLIC HERE PC | G70: =IFERROR(INDEX('🏢 Empresas'!$C$3:$C$200,MATCH($F70,'🏢 Empresas'!$B$3:$B$200,0)),"") | H70: =IFERROR(INDEX('🏢 Empresas'!$D$3:$D$200,MATCH($F70,'🏢 Empresas'!$B$3:$B$200,0)),"") | I70: =IFERROR(INDEX('🏢 Empresas'!$E$3:$E$200,MATCH($F70,'🏢 Empresas'!$B$3:$B$200,0)),"") | J70: =IFERROR(INDEX('🏢 Empresas'!$F$3:$F$200,MATCH($F70,'🏢 Empresas'!$B$3:$B$200,0)),"") | K70: Ing. Juan Carlos Sendón Varela. Mg. | L70: =IFERROR(INDEX('👥 Estudiantes'!$G$3:$G$200,MATCH($C70,'👥 Estudiantes'!$C$3:$C$200,0)),"") | M70: =IFERROR(INDEX('👥 Estudiantes'!$H$3:$H$200,MATCH($C70,'👥 Estudiantes'!$C$3:$C$200,0)),"") | N70: =IFERROR(INDEX('👥 Estudiantes'!$I$3:$I$200,MATCH($C70,'👥 Estudiantes'!$C$3:$C$200,0)),"") | O70: =IFERROR(INDEX('👥 Estudiantes'!$J$3:$J$200,MATCH($C70,'👥 Estudiantes'!$C$3:$C$200,0)),"") | P70: Infraestructura y Servidores
A71: =IF($C71="","",ROW()-2) | B71: =IFERROR(INDEX('👥 Estudiantes'!$B$3:$B$200,MATCH($C71,'👥 Estudiantes'!$C$3:$C$200,0)),"") | C71: Lucas Anchundia Luis Diego | D71: =IFERROR(INDEX('👥 Estudiantes'!$D$3:$D$200,MATCH($C71,'👥 Estudiantes'!$C$3:$C$200,0)),"") | E71: =IFERROR(INDEX('👥 Estudiantes'!$E$3:$E$200,MATCH($C71,'👥 Estudiantes'!$C$3:$C$200,0)),"") | F71: DISTRITO DE EDUCACION 13D02 | G71: =IFERROR(INDEX('🏢 Empresas'!$C$3:$C$200,MATCH($F71,'🏢 Empresas'!$B$3:$B$200,0)),"") | H71: =IFERROR(INDEX('🏢 Empresas'!$D$3:$D$200,MATCH($F71,'🏢 Empresas'!$B$3:$B$200,0)),"") | I71: =IFERROR(INDEX('�� Empresas'!$E$3:$E$200,MATCH($F71,'🏢 Empresas'!$B$3:$B$200,0)),"") | J71: =IFERROR(INDEX('🏢 Empresas'!$F$3:$F$200,MATCH($F71,'🏢 Empresas'!$B$3:$B$200,0)),"") | K71: Ing. Luis Jacinto Mendoza Cuzme. Mg. | L71: =IFERROR(INDEX('👥 Estudiantes'!$G$3:$G$200,MATCH($C71,'👥 Estudiantes'!$C$3:$C$200,0)),"") | M71: =IFERROR(INDEX('👥 Estudiantes'!$H$3:$H$200,MATCH($C71,'👥 Estudiantes'!$C$3:$C$200,0)),"") | N71: =IFERROR(INDEX('👥 Estudiantes'!$I$3:$I$200,MATCH($C71,'👥 Estudiantes'!$C$3:$C$200,0)),"") | O71: =IFERROR(INDEX('👥 Estudiantes'!$J$3:$J$200,MATCH($C71,'👥 Estudiantes'!$C$3:$C$200,0)),"") | P71: Redes y Comunicaciones
A72: =IF($C72="","",ROW()-2) | B72: =IFERROR(INDEX('👥 Estudiantes'!$B$3:$B$200,MATCH($C72,'👥 Estudiantes'!$C$3:$C$200,0)),"") | C72: Lucas Zambrano Gabriele | D72: =IFERROR(INDEX('👥 Estudiantes'!$D$3:$D$200,MATCH($C72,'👥 Estudiantes'!$C$3:$C$200,0)),"") | E72: =IFERROR(INDEX('👥 Estudiantes'!$E$3:$E$200,MATCH($C72,'👥 Estudiantes'!$C$3:$C$200,0)),"") | F72: MOVILIDAD DE MANTA-EP | G72: =IFERROR(INDEX('🏢 Empresas'!$C$3:$C$200,MATCH($F72,'🏢 Empresas'!$B$3:$B$200,0)),"") | H72: =IFERROR(INDEX('🏢 Empresas'!$D$3:$D$200,MATCH($F72,'🏢 Empresas'!$B$3:$B$200,0)),"") | I72: =IFERROR(INDEX('🏢 Empresas'!$E$3:$E$200,MATCH($F72,'🏢 Empresas'!$B$3:$B$200,0)),"") | J72: =IFERROR(INDEX('🏢 Empresas'!$F$3:$F$200,MATCH($F72,'🏢 Empresas'!$B$3:$B$200,0)),"") | K72: Ing. Carlos Manosalvas García. Mg. | L72: =IFERROR(INDEX('👥 Estudiantes'!$G$3:$G$200,MATCH($C72,'👥 Estudiantes'!$C$3:$C$200,0)),"") | M72: =IFERROR(INDEX('👥 Estudiantes'!$H$3:$H$200,MATCH($C72,'👥 Estudiantes'!$C$3:$C$200,0)),"") | N72: =IFERROR(INDEX('👥 Estudiantes'!$I$3:$I$200,MATCH($C72,'👥 Estudiantes'!$C$3:$C$200,0)),"") | O72: =IFERROR(INDEX('👥 Estudiantes'!$J$3:$J$200,MATCH($C72,'👥 Estudiantes'!$C$3:$C$200,0)),"") | P72: Sistemas
A73: =IF($C73="","",ROW()-2) | B73: =IFERROR(INDEX('👥 Estudiantes'!$B$3:$B$200,MATCH($C73,'👥 Estudiantes'!$C$3:$C$200,0)),"") | C73: Luzardo Alcivar Guillermo Andres | D73: =IFERROR(INDEX('👥 Estudiantes'!$D$3:$D$200,MATCH($C73,'👥 Estudiantes'!$C$3:$C$200,0)),"") | E73: =IFERROR(INDEX('👥 Estudiantes'!$E$3:$E$200,MATCH($C73,'👥 Estudiantes'!$C$3:$C$200,0)),"") | F73: GAD MANTA | G73: =IFERROR(INDEX('🏢 Empresas'!$C$3:$C$200,MATCH($F73,'🏢 Empresas'!$B$3:$B$200,0)),"") | H73: =IFERROR(INDEX('🏢 Empresas'!$D$3:$D$200,MATCH($F73,'🏢 Empresas'!$B$3:$B$200,0)),"") | I73: =IFERROR(INDEX('🏢 Empresas'!$E$3:$E$200,MATCH($F73,'🏢 Empresas'!$B$3:$B$200,0)),"") | J73: =IFERROR(INDEX('🏢 Empresas'!$F$3:$F$200,MATCH($F73,'🏢 Empresas'!$B$3:$B$200,0)),"") | K73: Ing. Hiraida Monserrate Santana Cedeño. Mg. | L73: =IFERROR(INDEX('👥 Estudiantes'!$G$3:$G$200,MATCH($C73,'👥 Estudiantes'!$C$3:$C$200,0)),"") | M73: =IFERROR(INDEX('👥 Estudiantes'!$H$3:$H$200,MATCH($C73,'👥 Estudiantes'!$C$3:$C$200,0)),"") | N73: =IFERROR(INDEX('👥 Estudiantes'!$I$3:$I$200,MATCH($C73,'👥 Estudiantes'!$C$3:$C$200,0)),"") | O73: =IFERROR(INDEX('👥 Estudiantes'!$J$3:$J$200,MATCH($C73,'👥 Estudiantes'!$C$3:$C$200,0)),"") | P73: Redes y Comunicaciones
A74: =IF($C74="","",ROW()-2) | B74: =IFERROR(INDEX('👥 Estudiantes'!$B$3:$B$200,MATCH($C74,'👥 Estudiantes'!$C$3:$C$200,0)),"") | C74: López Lascano Anthony Agustín | D74: =IFERROR(INDEX('👥 Estudiantes'!$D$3:$D$200,MATCH($C74,'👥 Estudiantes'!$C$3:$C$200,0)),"") | E74: =IFERROR(INDEX('👥 Estudiantes'!$E$3:$E$200,MATCH($C74,'👥 Estudiantes'!$C$3:$C$200,0)),"") | F74: MANABI PRODUCE | G74: =IFERROR(INDEX('🏢 Empresas'!$C$3:$C$200,MATCH($F74,'🏢 Empresas'!$B$3:$B$200,0)),"") | H74: =IFERROR(INDEX('🏢 Empresas'!$D$3:$D$200,MATCH($F74,'🏢 Empresas'!$B$3:$B$200,0)),"") | I74: =IFERROR(INDEX('🏢 Empresas'!$E$3:$E$200,MATCH($F74,'🏢 Empresas'!$B$3:$B$200,0)),"") | J74: =IFERROR(INDEX('🏢 Empresas'!$F$3:$F$200,MATCH($F74,'🏢 Empresas'!$B$3:$B$200,0)),"") | K74: Ing. Walter Colón García Vélez. Mg. | L74: =IFERROR(INDEX('👥 Estudiantes'!$G$3:$G$200,MATCH($C74,'👥 Estudiantes'!$C$3:$C$200,0)),"") | M74: =IFERROR(INDEX('👥 Estudiantes'!$H$3:$H$200,MATCH($C74,'👥 Estudiantes'!$C$3:$C$200,0)),"") | N74: =IFERROR(INDEX('👥 Estudiantes'!$I$3:$I$200,MATCH($C74,'👥 Estudiantes'!$C$3:$C$200,0)),"") | O74: =IFERROR(INDEX('👥 Estudiantes'!$J$3:$J$200,MATCH($C74,'👥 Estudiantes'!$C$3:$C$200,0)),"") | P74: Redes y Comunicaciones
A75: =IF($C75="","",ROW()-2) | B75: =IFERROR(INDEX('👥 Estudiantes'!$B$3:$B$200,MATCH($C75,'👥 Estudiantes'!$C$3:$C$200,0)),"") | C75: Macias Bravo Melina Lissette | D75: =IFERROR(INDEX('👥 Estudiantes'!$D$3:$D$200,MATCH($C75,'👥 Estudiantes'!$C$3:$C$200,0)),"") | E75: =IFERROR(INDEX('👥 Estudiantes'!$E$3:$E$200,MATCH($C75,'👥 Estudiantes'!$C$3:$C$200,0)),"") | F75: MOVILIDAD DE MANTA-EP | G75: =IFERROR(INDEX('🏢 Empresas'!$C$3:$C$200,MATCH($F75,'🏢 Empresas'!$B$3:$B$200,0)),"") | H75: =IFERROR(INDEX('🏢 Empresas'!$D$3:$D$200,MATCH($F75,'🏢 Empresas'!$B$3:$B$200,0)),"") | I75: =IFERROR(INDEX('🏢 Empresas'!$E$3:$E$200,MATCH($F75,'🏢 Empresas'!$B$3:$B$200,0)),"") | J75: =IFERROR(INDEX('🏢 Empresas'!$F$3:$F$200,MATCH($F75,'🏢 Empresas'!$B$3:$B$200,0)),"") | K75: Ing. Carlos Manosalvas García. Mg. | L75: =IFERROR(INDEX('👥 Estudiantes'!$G$3:$G$200,MATCH($C75,'👥 Estudiantes'!$C$3:$C$200,0)),"") | M75: =IFERROR(INDEX('👥 Estudiantes'!$H$3:$H$200,MATCH($C75,'👥 Estudiantes'!$C$3:$C$200,0)),"") | N75: =IFERROR(INDEX('👥 Estudiantes'!$I$3:$I$200,MATCH($C75,'👥 Estudiantes'!$C$3:$C$200,0)),"") | O75: =IFERROR(INDEX('👥 Estudiantes'!$J$3:$J$200,MATCH($C75,'👥 Estudiantes'!$C$3:$C$200,0)),"") | P75: TI
A76: =IF($C76="","",ROW()-2) | B76: =IFERROR(INDEX('👥 Estudiantes'!$B$3:$B$200,MATCH($C76,'👥 Estudiantes'!$C$3:$C$200,0)),"") | C76: Macias Faubla Bryan José | D76: =IFERROR(INDEX('👥 Estudiantes'!$D$3:$D$200,MATCH($C76,'👥 Estudiantes'!$C$3:$C$200,0)),"") | E76: =IFERROR(INDEX('👥 Estudiantes'!$E$3:$E$200,MATCH($C76,'👥 Estudiantes'!$C$3:$C$200,0)),"") | F76: ATUKHOSTING | G76: =IFERROR(INDEX('🏢 Empresas'!$C$3:$C$200,MATCH($F76,'🏢 Empresas'!$B$3:$B$200,0)),"") | H76: =IFERROR(INDEX('🏢 Empresas'!$D$3:$D$200,MATCH($F76,'🏢 Empresas'!$B$3:$B$200,0)),"") | I76: =IFERROR(INDEX('🏢 Empresas'!$E$3:$E$200,MATCH($F76,'🏢 Empresas'!$B$3:$B$200,0)),"") | J76: =IFERROR(INDEX('🏢 Empresas'!$F$3:$F$200,MATCH($F76,'🏢 Empresas'!$B$3:$B$200,0)),"") | K76: Ing. Juan Carlos Sendón Varela. Mg. | L76: =IFERROR(INDEX('👥 Estudiantes'!$G$3:$G$200,MATCH($C76,'👥 Estudiantes'!$C$3:$C$200,0)),"") | M76: =IFERROR(INDEX('👥 Estudiantes'!$H$3:$H$200,MATCH($C76,'👥 Estudiantes'!$C$3:$C$200,0)),"") | N76: =IFERROR(INDEX('👥 Estudiantes'!$I$3:$I$200,MATCH($C76,'👥 Estudiantes'!$C$3:$C$200,0)),"") | O76: =IFERROR(INDEX('👥 Estudiantes'!$J$3:$J$200,MATCH($C76,'👥 Estudiantes'!$C$3:$C$200,0)),"") | P76: Infraestructura y Servidores
A77: =IF($C77="","",ROW()-2) | B77: =IFERROR(INDEX('👥 Estudiantes'!$B$3:$B$200,MATCH($C77,'👥 Estudiantes'!$C$3:$C$200,0)),"") | C77: Macias Lugo Jesus Fernando | D77: =IFERROR(INDEX('👥 Estudiantes'!$D$3:$D$200,MATCH($C77,'👥 Estudiantes'!$C$3:$C$200,0)),"") | E77: =IFERROR(INDEX('👥 Estudiantes'!$E$3:$E$200,MATCH($C77,'👥 Estudiantes'!$C$3:$C$200,0)),"") | F77: ZGAMES | G77: =IFERROR(INDEX('🏢 Empresas'!$C$3:$C$200,MATCH($F77,'🏢 Empresas'!$B$3:$B$200,0)),"") | H77: =IFERROR(INDEX('🏢 Empresas'!$D$3:$D$200,MATCH($F77,'🏢 Empresas'!$B$3:$B$200,0)),"") | I77: =IFERROR(INDEX('🏢 Empresas'!$E$3:$E$200,MATCH($F77,'🏢 Empresas'!$B$3:$B$200,0)),"") | J77: =IFERROR(INDEX('🏢 Empresas'!$F$3:$F$200,MATCH($F77,'🏢 Empresas'!$B$3:$B$200,0)),"") | K77: Ing. Walter Colón García Vélez. Mg. | L77: =IFERROR(INDEX('👥 Estudiantes'!$G$3:$G$200,MATCH($C77,'👥 Estudiantes'!$C$3:$C$200,0)),"") | M77: =IFERROR(INDEX('👥 Estudiantes'!$H$3:$H$200,MATCH($C77,'👥 Estudiantes'!$C$3:$C$200,0)),"") | N77: =IFERROR(INDEX('👥 Estudiantes'!$I$3:$I$200,MATCH($C77,'👥 Estudiantes'!$C$3:$C$200,0)),"") | O77: =IFERROR(INDEX('👥 Estudiantes'!$J$3:$J$200,MATCH($C77,'👥 Estudiantes'!$C$3:$C$200,0)),"") | P77: Redes y Comunicaciones
A78: =IF($C78="","",ROW()-2) | B78: =IFERROR(INDEX('👥 Estudiantes'!$B$3:$B$200,MATCH($C78,'👥 Estudiantes'!$C$3:$C$200,0)),"") | C78: Macías Sosa Carlos Johan | D78: =IFERROR(INDEX('👥 Estudiantes'!$D$3:$D$200,MATCH($C78,'👥 Estudiantes'!$C$3:$C$200,0)),"") | E78: =IFERROR(INDEX('👥 Estudiantes'!$E$3:$E$200,MATCH($C78,'👥 Estudiantes'!$C$3:$C$200,0)),"") | F78: DISTRITO DE SALUD D1302 | G78: =IFERROR(INDEX('🏢 Empresas'!$C$3:$C$200,MATCH($F78,'🏢 Empresas'!$B$3:$B$200,0)),"") | H78: =IFERROR(INDEX('🏢 Empresas'!$D$3:$D$200,MATCH($F78,'🏢 Empresas'!$B$3:$B$200,0)),"") | I78: =IFERROR(INDEX('🏢 Empresas'!$E$3:$E$200,MATCH($F78,'🏢 Empresas'!$B$3:$B$200,0)),"") | J78: =IFERROR(INDEX('🏢 Empresas'!$F$3:$F$200,MATCH($F78,'🏢 Empresas'!$B$3:$B$200,0)),"") | K78: Ing. Carlos Manosalvas García. Mg. | L78: =IFERROR(INDEX('👥 Estudiantes'!$G$3:$G$200,MATCH($C78,'👥 Estudiantes'!$C$3:$C$200,0)),"") | M78: =IFERROR(INDEX('👥 Estudiantes'!$H$3:$H$200,MATCH($C78,'👥 Estudiantes'!$C$3:$C$200,0)),"") | N78: =IFERROR(INDEX('👥 Estudiantes'!$I$3:$I$200,MATCH($C78,'👥 Estudiantes'!$C$3:$C$200,0)),"") | O78: =IFERROR(INDEX('👥 Estudiantes'!$J$3:$J$200,MATCH($C78,'👥 Estudiantes'!$C$3:$C$200,0)),"") | P78: Soporte Técnico
A79: =IF($C79="","",ROW()-2) | B79: =IFERROR(INDEX('👥 Estudiantes'!$B$3:$B$200,MATCH($C79,'👥 Estudiantes'!$C$3:$C$200,0)),"") | C79: Mejía Párraga Yender David | D79: =IFERROR(INDEX('👥 Estudiantes'!$D$3:$D$200,MATCH($C79,'👥 Estudiantes'!$C$3:$C$200,0)),"") | E79: =IFERROR(INDEX('👥 Estudiantes'!$E$3:$E$200,MATCH($C79,'👥 Estudiantes'!$C$3:$C$200,0)),"") | F79: ATUKHOSTING | G79: =IFERROR(INDEX('🏢 Empresas'!$C$3:$C$200,MATCH($F79,'🏢 Empresas'!$B$3:$B$200,0)),"") | H79: =IFERROR(INDEX('🏢 Empresas'!$D$3:$D$200,MATCH($F79,'🏢 Empresas'!$B$3:$B$200,0)),"") | I79: =IFERROR(INDEX('🏢 Empresas'!$E$3:$E$200,MATCH($F79,'🏢 Empresas'!$B$3:$B$200,0)),"") | J79: =IFERROR(INDEX('🏢 Empresas'!$F$3:$F$200,MATCH($F79,'🏢 Empresas'!$B$3:$B$200,0)),"") | K79: Ing. Juan Carlos Sendón Varela. Mg. | L79: =IFERROR(INDEX('👥 Estudiantes'!$G$3:$G$200,MATCH($C79,'👥 Estudiantes'!$C$3:$C$200,0)),"") | M79: =IFERROR(INDEX('👥 Estudiantes'!$H$3:$H$200,MATCH($C79,'👥 Estudiantes'!$C$3:$C$200,0)),"") | N79: =IFERROR(INDEX('👥 Estudiantes'!$I$3:$I$200,MATCH($C79,'👥 Estudiantes'!$C$3:$C$200,0)),"") | O79: =IFERROR(INDEX('👥 Estudiantes'!$J$3:$J$200,MATCH($C79,'👥 Estudiantes'!$C$3:$C$200,0)),"") | P79: Infraestructura y Servidores
A80: =IF($C80="","",ROW()-2) | B80: =IFERROR(INDEX('👥 Estudiantes'!$B$3:$B$200,MATCH($C80,'👥 Estudiantes'!$C$3:$C$200,0)),"") | C80: Mendoza Bazurto Fabricio Jesús | D80: =IFERROR(INDEX('👥 Estudiantes'!$D$3:$D$200,MATCH($C80,'👥 Estudiantes'!$C$3:$C$200,0)),"") | E80: =IFERROR(INDEX('👥 Estudiantes'!$E$3:$E$200,MATCH($C80,'👥 Estudiantes'!$C$3:$C$200,0)),"") | F80: HOSPITAL RODRIGUEZ ZAMBRANO | G80: =IFERROR(INDEX('🏢 Empresas'!$C$3:$C$200,MATCH($F80,'🏢 Empresas'!$B$3:$B$200,0)),"") | H80: =IFERROR(INDEX('🏢 Empresas'!$D$3:$D$200,MATCH($F80,'🏢 Empresas'!$B$3:$B$200,0)),"") | I80: =IFERROR(INDEX('🏢 Empresas'!$E$3:$E$200,MATCH($F80,'🏢 Empresas'!$B$3:$B$200,0)),"") | J80: =IFERROR(INDEX('🏢 Empresas'!$F$3:$F$200,MATCH($F80,'🏢 Empresas'!$B$3:$B$200,0)),"") | K80: Ing. Marco Wellington Ayovi Ramirez. PhD. | L80: =IFERROR(INDEX('👥 Estudiantes'!$G$3:$G$200,MATCH($C80,'👥 Estudiantes'!$C$3:$C$200,0)),"") | M80: =IFERROR(INDEX('👥 Estudiantes'!$H$3:$H$200,MATCH($C80,'👥 Estudiantes'!$C$3:$C$200,0)),"") | N80: =IFERROR(INDEX('👥 Estudiantes'!$I$3:$I$200,MATCH($C80,'👥 Estudiantes'!$C$3:$C$200,0)),"") | O80: =IFERROR(INDEX('👥 Estudiantes'!$J$3:$J$200,MATCH($C80,'👥 Estudiantes'!$C$3:$C$200,0)),"") | P80: Sistemas
A81: =IF($C81="","",ROW()-2) | B81: =IFERROR(INDEX('👥 Estudiantes'!$B$3:$B$200,MATCH($C81,'👥 Estudiantes'!$C$3:$C$200,0)),"") | C81: Mendoza Mendoza Michael Steven | D81: =IFERROR(INDEX('👥 Estudiantes'!$D$3:$D$200,MATCH($C81,'👥 Estudiantes'!$C$3:$C$200,0)),"") | E81: =IFERROR(INDEX('👥 Estudiantes'!$E$3:$E$200,MATCH($C81,'👥 Estudiantes'!$C$3:$C$200,0)),"") | F81: ULEAM-EP | G81: =IFERROR(INDEX('🏢 Empresas'!$C$3:$C$200,MATCH($F81,'🏢 Empresas'!$B$3:$B$200,0)),"") | H81: =IFERROR(INDEX('🏢 Empresas'!$D$3:$D$200,MATCH($F81,'🏢 Empresas'!$B$3:$B$200,0)),"") | I81: =IFERROR(INDEX('🏢 Empresas'!$E$3:$E$200,MATCH($F81,'🏢 Empresas'!$B$3:$B$200,0)),"") | J81: =IFERROR(INDEX('🏢 Empresas'!$F$3:$F$200,MATCH($F81,'🏢 Empresas'!$B$3:$B$200,0)),"") | K81: Ing. Carlos Manosalvas García. Mg. | L81: =IFERROR(INDEX('👥 Estudiantes'!$G$3:$G$200,MATCH($C81,'👥 Estudiantes'!$C$3:$C$200,0)),"") | M81: =IFERROR(INDEX('👥 Estudiantes'!$H$3:$H$200,MATCH($C81,'👥 Estudiantes'!$C$3:$C$200,0)),"") | N81: =IFERROR(INDEX('👥 Estudiantes'!$I$3:$I$200,MATCH($C81,'👥 Estudiantes'!$C$3:$C$200,0)),"") | O81: =IFERROR(INDEX('👥 Estudiantes'!$J$3:$J$200,MATCH($C81,'👥 Estudiantes'!$C$3:$C$200,0)),"") | P81: Soporte Técnico
A82: =IF($C82="","",ROW()-2) | B82: =IFERROR(INDEX('👥 Estudiantes'!$B$3:$B$200,MATCH($C82,'👥 Estudiantes'!$C$3:$C$200,0)),"") | C82: Mera Mendoza Rubén Darío | D82: =IFERROR(INDEX('👥 Estudiantes'!$D$3:$D$200,MATCH($C82,'👥 Estudiantes'!$C$3:$C$200,0)),"") | E82: =IFERROR(INDEX('👥 Estudiantes'!$E$3:$E$200,MATCH($C82,'👥 Estudiantes'!$C$3:$C$200,0)),"") | F82: DIIT ULEAM | G82: =IFERROR(INDEX('🏢 Empresas'!$C$3:$C$200,MATCH($F82,'🏢 Empresas'!$B$3:$B$200,0)),"") | H82: =IFERROR(INDEX('🏢 Empresas'!$D$3:$D$200,MATCH($F82,'🏢 Empresas'!$B$3:$B$200,0)),"") | I82: =IFERROR(INDEX('🏢 Empresas'!$E$3:$E$200,MATCH($F82,'🏢 Empresas'!$B$3:$B$200,0)),"") | J82: =IFERROR(INDEX('🏢 Empresas'!$F$3:$F$200,MATCH($F82,'🏢 Empresas'!$B$3:$B$200,0)),"") | K82: Ing. Juan Carlos Sendón Varela. Mg. | L82: =IFERROR(INDEX('👥 Estudiantes'!$G$3:$G$200,MATCH($C82,'👥 Estudiantes'!$C$3:$C$200,0)),"") | M82: =IFERROR(INDEX('👥 Estudiantes'!$H$3:$H$200,MATCH($C82,'👥 Estudiantes'!$C$3:$C$200,0)),"") | N82: =IFERROR(INDEX('👥 Estudiantes'!$I$3:$I$200,MATCH($C82,'👥 Estudiantes'!$C$3:$C$200,0)),"") | O82: =IFERROR(INDEX('👥 Estudiantes'!$J$3:$J$200,MATCH($C82,'👥 Estudiantes'!$C$3:$C$200,0)),"") | P82: Desarrollo de Software
A83: =IF($C83="","",ROW()-2) | B83: =IFERROR(INDEX('👥 Estudiantes'!$B$3:$B$200,MATCH($C83,'👥 Estudiantes'!$C$3:$C$200,0)),"") | C83: Mero Figueroa Jeremy Alan | D83: =IFERROR(INDEX('👥 Estudiantes'!$D$3:$D$200,MATCH($C83,'👥 Estudiantes'!$C$3:$C$200,0)),"") | E83: =IFERROR(INDEX('👥 Estudiantes'!$E$3:$E$200,MATCH($C83,'👥 Estudiantes'!$C$3:$C$200,0)),"") | F83: EPAM | G83: =IFERROR(INDEX('🏢 Empresas'!$C$3:$C$200,MATCH($F83,'🏢 Empresas'!$B$3:$B$200,0)),"") | H83: =IFERROR(INDEX('🏢 Empresas'!$D$3:$D$200,MATCH($F83,'🏢 Empresas'!$B$3:$B$200,0)),"") | I83: =IFERROR(INDEX('🏢 Empresas'!$E$3:$E$200,MATCH($F83,'🏢 Empresas'!$B$3:$B$200,0)),"") | J83: =IFERROR(INDEX('🏢 Empresas'!$F$3:$F$200,MATCH($F83,'🏢 Empresas'!$B$3:$B$200,0)),"") | K83: Ing. Juan Carlos Sendón Varela. Mg. | L83: =IFERROR(INDEX('👥 Estudiantes'!$G$3:$G$200,MATCH($C83,'👥 Estudiantes'!$C$3:$C$200,0)),"") | M83: =IFERROR(INDEX('👥 Estudiantes'!$H$3:$H$200,MATCH($C83,'👥 Estudiantes'!$C$3:$C$200,0)),"") | N83: =IFERROR(INDEX('👥 Estudiantes'!$I$3:$I$200,MATCH($C83,'👥 Estudiantes'!$C$3:$C$200,0)),"") | O83: =IFERROR(INDEX('👥 Estudiantes'!$J$3:$J$200,MATCH($C83,'👥 Estudiantes'!$C$3:$C$200,0)),"") | P83: TI
... A139: =IF($C139="","",ROW()-2) | B139: =IFERROR(INDEX('👥 Estudiantes'!$B$3:$B$200,MATCH($C139,'👥 Estudiantes'!$C$3:$C$200,0)),"") | C139: Zamora Piguave Miguel Ignacio | D139: =IFERROR(INDEX('👥 Estudiantes'!$D$3:$D$200,MATCH($C139,'👥 Estudiantes'!$C$3:$C$200,0)),"") | E139: =IFERROR(INDEX('👥 Estudiantes'!$E$3:$E$200,MATCH($C139,'👥 Estudiantes'!$C$3:$C$200,0)),"") | F139: PROYECTO DE INVESTIGACIÓN EL ROL DE LAS TECNOLOGÍAS EN LA EDUCACIÓN SUPERIOR | G139: =IFERROR(INDEX('🏢 Empresas'!$C$3:$C$200,MATCH($F139,'🏢 Empresas'!$B$3:$B$200,0)),"") | H139: =IFERROR(INDEX('🏢 Empresas'!$D$3:$D$200,MATCH($F139,'🏢 Empresas'!$B$3:$B$200,0)),"") | I139: =IFERROR(INDEX('🏢 Empresas'!$E$3:$E$200,MATCH($F139,'🏢 Empresas'!$B$3:$B$200,0)),"") | J139: =IFERROR(INDEX('🏢 Empresas'!$F$3:$F$200,MATCH($F139,'🏢 Empresas'!$B$3:$B$200,0)),"") | K139: Ing. Robert Wilfrido Moreira Centeno, Mg | L139: =IFERROR(INDEX('👥 Estudiantes'!$G$3:$G$200,MATCH($C139,'👥 Estudiantes'!$C$3:$C$200,0)),"") | M139: =IFERROR(INDEX('👥 Estudiantes'!$H$3:$H$200,MATCH($C139,'👥 Estudiantes'!$C$3:$C$200,0)),"") | N139: =IFERROR(INDEX('👥 Estudiantes'!$I$3:$I$200,MATCH($C139,'👥 Estudiantes'!$C$3:$C$200,0)),"") | O139: =IFERROR(INDEX('👥 Estudiantes'!$J$3:$J$200,MATCH($C139,'👥 Estudiantes'!$C$3:$C$200,0)),"") | P139: Desarrollo de Software
A140: =IF($C140="","",ROW()-2) | B140: =IFERROR(INDEX('👥 Estudiantes'!$B$3:$B$200,MATCH($C140,'👥 Estudiantes'!$C$3:$C$200,0)),"") | D140: =IFERROR(INDEX('👥 Estudiantes'!$D$3:$D$200,MATCH($C140,'👥 Estudiantes'!$C$3:$C$200,0)),"") | E140: =IFERROR(INDEX('👥 Estudiantes'!$E$3:$E$200,MATCH($C140,'👥 Estudiantes'!$C$3:$C$200,0)),"") | G140: =IFERROR(INDEX('🏢 Empresas'!$C$3:$C$200,MATCH($F140,'🏢 Empresas'!$B$3:$B$200,0)),"") | H140: =IFERROR(INDEX('🏢 Empresas'!$D$3:$D$200,MATCH($F140,'🏢 Empresas'!$B$3:$B$200,0)),"") | I140: =IFERROR(INDEX('🏢 Empresas'!$E$3:$E$200,MATCH($F140,'🏢 Empresas'!$B$3:$B$200,0)),"") | J140: =IFERROR(INDEX('🏢 Empresas'!$F$3:$F$200,MATCH($F140,'🏢 Empresas'!$B$3:$B$200,0)),"") | L140: =IFERROR(INDEX('👥 Estudiantes'!$G$3:$G$200,MATCH($C140,'👥 Estudiantes'!$C$3:$C$200,0)),"") | M140: =IFERROR(INDEX('👥 Estudiantes'!$H$3:$H$200,MATCH($C140,'👥 Estudiantes'!$C$3:$C$200,0)),"") | N140: =IFERROR(INDEX('👥 Estudiantes'!$I$3:$I$200,MATCH($C140,'👥 Estudiantes'!$C$3:$C$200,0)),"") | O140: =IFERROR(INDEX('👥 Estudiantes'!$J$3:$J$200,MATCH($C140,'👥 Estudiantes'!$C$3:$C$200,0)),"")
A141: =IF($C141="","",ROW()-2) | B141: =IFERROR(INDEX('👥 Estudiantes'!$B$3:$B$200,MATCH($C141,'👥 Estudiantes'!$C$3:$C$200,0)),"") | D141: =IFERROR(INDEX('👥 Estudiantes'!$D$3:$D$200,MATCH($C141,'👥 Estudiantes'!$C$3:$C$200,0)),"") | E141: =IFERROR(INDEX('👥 Estudiantes'!$E$3:$E$200,MATCH($C141,'👥 Estudiantes'!$C$3:$C$200,0)),"") | G141: =IFERROR(INDEX('🏢 Empresas'!$C$3:$C$200,MATCH($F141,'🏢 Empresas'!$B$3:$B$200,0)),"") | H141: =IFERROR(INDEX('🏢 Empresas'!$D$3:$D$200,MATCH($F141,'🏢 Empresas'!$B$3:$B$200,0)),"") | I141: =IFERROR(INDEX('🏢 Empresas'!$E$3:$E$200,MATCH($F141,'🏢 Empresas'!$B$3:$B$200,0)),"") | J141: =IFERROR(INDEX('🏢 Empresas'!$F$3:$F$200,MATCH($F141,'🏢 Empresas'!$B$3:$B$200,0)),"") | L141: =IFERROR(INDEX('👥 Estudiantes'!$G$3:$G$200,MATCH($C141,'👥 Estudiantes'!$C$3:$C$200,0)),"") | M141: =IFERROR(INDEX('👥 Estudiantes'!$H$3:$H$200,MATCH($C141,'👥 Estudiantes'!$C$3:$C$200,0)),"") | N141: =IFERROR(INDEX('👥 Estudiantes'!$I$3:$I$200,MATCH($C141,'👥 Estudiantes'!$C$3:$C$200,0)),"") | O141: =IFERROR(INDEX('👥 Estudiantes'!$J$3:$J$200,MATCH($C141,'👥 Estudiantes'!$C$3:$C$200,0)),"")
A142: =IF($C142="","",ROW()-2) | B142: =IFERROR(INDEX('👥 Estudiantes'!$B$3:$B$200,MATCH($C142,'👥 Estudiantes'!$C$3:$C$200,0)),"") | D142: =IFERROR(INDEX('👥 Estudiantes'!$D$3:$D$200,MATCH($C142,'👥 Estudiantes'!$C$3:$C$200,0)),"") | E142: =IFERROR(INDEX('👥 Estudiantes'!$E$3:$E$200,MATCH($C142,'👥 Estudiantes'!$C$3:$C$200,0)),"") | G142: =IFERROR(INDEX('🏢 Empresas'!$C$3:$C$200,MATCH($F142,'🏢 Empresas'!$B$3:$B$200,0)),"") | H142: =IFERROR(INDEX('🏢 Empresas'!$D$3:$D$200,MATCH($F142,'🏢 Empresas'!$B$3:$B$200,0)),"") | I142: =IFERROR(INDEX('🏢 Empresas'!$E$3:$E$200,MATCH($F142,'🏢 Empresas'!$B$3:$B$200,0)),"") | J142: =IFERROR(INDEX('🏢 Empresas'!$F$3:$F$200,MATCH($F142,'🏢 Empresas'!$B$3:$B$200,0)),"") | L142: =IFERROR(INDEX('👥 Estudiantes'!$G$3:$G$200,MATCH($C142,'👥 Estudiantes'!$C$3:$C$200,0)),"") | M142: =IFERROR(INDEX('👥 Estudiantes'!$H$3:$H$200,MATCH($C142,'👥 Estudiantes'!$C$3:$C$200,0)),"") | N142: =IFERROR(INDEX('👥 Estudiantes'!$I$3:$I$200,MATCH($C142,'👥 Estudiantes'!$C$3:$C$200,0)),"") | O142: =IFERROR(INDEX('👥 Estudiantes'!$J$3:$J$200,MATCH($C142,'👥 Estudiantes'!$C$3:$C$200,0)),"")
A143: =IF($C143="","",ROW()-2) | B143: =IFERROR(INDEX('👥 Estudiantes'!$B$3:$B$200,MATCH($C143,'👥 Estudiantes'!$C$3:$C$200,0)),"") | D143: =IFERROR(INDEX('👥 Estudiantes'!$D$3:$D$200,MATCH($C143,'👥 Estudiantes'!$C$3:$C$200,0)),"") | E143: =IFERROR(INDEX('👥 Estudiantes'!$E$3:$E$200,MATCH($C143,'👥 Estudiantes'!$C$3:$C$200,0)),"") | G143: =IFERROR(INDEX('🏢 Empresas'!$C$3:$C$200,MATCH($F143,'🏢 Empresas'!$B$3:$B$200,0)),"") | H143: =IFERROR(INDEX('🏢 Empresas'!$D$3:$D$200,MATCH($F143,'🏢 Empresas'!$B$3:$B$200,0)),"") | I143: =IFERROR(INDEX('🏢 Empresas'!$E$3:$E$200,MATCH($F143,'🏢 Empresas'!$B$3:$B$200,0)),"") | J143: =IFERROR(INDEX('🏢 Empresas'!$F$3:$F$200,MATCH($F143,'🏢 Empresas'!$B$3:$B$200,0)),"") | L143: =IFERROR(INDEX('👥 Estudiantes'!$G$3:$G$200,MATCH($C143,'👥 Estudiantes'!$C$3:$C$200,0)),"") | M143: =IFERROR(INDEX('👥 Estudiantes'!$H$3:$H$200,MATCH($C143,'👥 Estudiantes'!$C$3:$C$200,0)),"") | N143: =IFERROR(INDEX('👥 Estudiantes'!$I$3:$I$200,MATCH($C143,'👥 Estudiantes'!$C$3:$C$200,0)),"") | O143: =IFERROR(INDEX('👥 Estudiantes'!$J$3:$J$200,MATCH($C143,'👥 Estudiantes'!$C$3:$C$200,0)),"")
A144: =IF($C144="","",ROW()-2) | B144: =IFERROR(INDEX('👥 Estudiantes'!$B$3:$B$200,MATCH($C144,'👥 Estudiantes'!$C$3:$C$200,0)),"") | D144: =IFERROR(INDEX('👥 Estudiantes'!$D$3:$D$200,MATCH($C144,'👥 Estudiantes'!$C$3:$C$200,0)),"") | E144: =IFERROR(INDEX('👥 Estudiantes'!$E$3:$E$200,MATCH($C144,'👥 Estudiantes'!$C$3:$C$200,0)),"") | G144: =IFERROR(INDEX('🏢 Empresas'!$C$3:$C$200,MATCH($F144,'🏢 Empresas'!$B$3:$B$200,0)),"") | H144: =IFERROR(INDEX('🏢 Empresas'!$D$3:$D$200,MATCH($F144,'🏢 Empresas'!$B$3:$B$200,0)),"") | I144: =IFERROR(INDEX('🏢 Empresas'!$E$3:$E$200,MATCH($F144,'🏢 Empresas'!$B$3:$B$200,0)),"") | J144: =IFERROR(INDEX('🏢 Empresas'!$F$3:$F$200,MATCH($F144,'🏢 Empresas'!$B$3:$B$200,0)),"") | L144: =IFERROR(INDEX('👥 Estudiantes'!$G$3:$G$200,MATCH($C144,'👥 Estudiantes'!$C$3:$C$200,0)),"") | M144: =IFERROR(INDEX('👥 Estudiantes'!$H$3:$H$200,MATCH($C144,'👥 Estudiantes'!$C$3:$C$200,0)),"") | N144: =IFERROR(INDEX('👥 Estudiantes'!$I$3:$I$200,MATCH($C144,'👥 Estudiantes'!$C$3:$C$200,0)),"") | O144: =IFERROR(INDEX('👥 Estudiantes'!$J$3:$J$200,MATCH($C144,'👥 Estudiantes'!$C$3:$C$200,0)),"")
A145: =IF($C145="","",ROW()-2) | B145: =IFERROR(INDEX('👥 Estudiantes'!$B$3:$B$200,MATCH($C145,'👥 Estudiantes'!$C$3:$C$200,0)),"") | D145: =IFERROR(INDEX('👥 Estudiantes'!$D$3:$D$200,MATCH($C145,'👥 Estudiantes'!$C$3:$C$200,0)),"") | E145: =IFERROR(INDEX('👥 Estudiantes'!$E$3:$E$200,MATCH($C145,'👥 Estudiantes'!$C$3:$C$200,0)),"") | G145: =IFERROR(INDEX('🏢 Empresas'!$C$3:$C$200,MATCH($F145,'🏢 Empresas'!$B$3:$B$200,0)),"") | H145: =IFERROR(INDEX('🏢 Empresas'!$D$3:$D$200,MATCH($F145,'🏢 Empresas'!$B$3:$B$200,0)),"") | I145: =IFERROR(INDEX('🏢 Empresas'!$E$3:$E$200,MATCH($F145,'🏢 Empresas'!$B$3:$B$200,0)),"") | J145: =IFERROR(INDEX('🏢 Empresas'!$F$3:$F$200,MATCH($F145,'🏢 Empresas'!$B$3:$B$200,0)),"") | L145: =IFERROR(INDEX('👥 Estudiantes'!$G$3:$G$200,MATCH($C145,'👥 Estudiantes'!$C$3:$C$200,0)),"") | M145: =IFERROR(INDEX('👥 Estudiantes'!$H$3:$H$200,MATCH($C145,'👥 Estudiantes'!$C$3:$C$200,0)),"") | N145: =IFERROR(INDEX('👥 Estudiantes'!$I$3:$I$200,MATCH($C145,'👥 Estudiantes'!$C$3:$C$200,0)),"") | O145: =IFERROR(INDEX('👥 Estudiantes'!$J$3:$J$200,MATCH($C145,'👥 Estudiantes'!$C$3:$C$200,0)),"")
A146: =IF($C146="","",ROW()-2) | B146: =IFERROR(INDEX('👥 Estudiantes'!$B$3:$B$200,MATCH($C146,'👥 Estudiantes'!$C$3:$C$200,0)),"") | D146: =IFERROR(INDEX('👥 Estudiantes'!$D$3:$D$200,MATCH($C146,'👥 Estudiantes'!$C$3:$C$200,0)),"") | E146: =IFERROR(INDEX('👥 Estudiantes'!$E$3:$E$200,MATCH($C146,'👥 Estudiantes'!$C$3:$C$200,0)),"") | G146: =IFERROR(INDEX('🏢 Empresas'!$C$3:$C$200,MATCH($F146,'🏢 Empresas'!$B$3:$B$200,0)),"") | H146: =IFERROR(INDEX('🏢 Empresas'!$D$3:$D$200,MATCH($F146,'🏢 Empresas'!$B$3:$B$200,0)),"") | I146: =IFERROR(INDEX('🏢 Empresas'!$E$3:$E$200,MATCH($F146,'🏢 Empresas'!$B$3:$B$200,0)),"") | J146: =IFERROR(INDEX('🏢 Empresas'!$F$3:$F$200,MATCH($F146,'🏢 Empresas'!$B$3:$B$200,0)),"") | L146: =IFERROR(INDEX('👥 Estudiantes'!$G$3:$G$200,MATCH($C146,'👥 Estudiantes'!$C$3:$C$200,0)),"") | M146: =IFERROR(INDEX('👥 Estudiantes'!$H$3:$H$200,MATCH($C146,'👥 Estudiantes'!$C$3:$C$200,0)),"") | N146: =IFERROR(INDEX('👥 Estudiantes'!$I$3:$I$200,MATCH($C146,'👥 Estudiantes'!$C$3:$C$200,0)),"") | O146: =IFERROR(INDEX('👥 Estudiantes'!$J$3:$J$200,MATCH($C146,'👥 Estudiantes'!$C$3:$C$200,0)),"")
A147: =IF($C147="","",ROW()-2) | B147: =IFERROR(INDEX('👥 Estudiantes'!$B$3:$B$200,MATCH($C147,'👥 Estudiantes'!$C$3:$C$200,0)),"") | D147: =IFERROR(INDEX('👥 Estudiantes'!$D$3:$D$200,MATCH($C147,'👥 Estudiantes'!$C$3:$C$200,0)),"") | E147: =IFERROR(INDEX('👥 Estudiantes'!$E$3:$E$200,MATCH($C147,'👥 Estudiantes'!$C$3:$C$200,0)),"") | G147: =IFERROR(INDEX('🏢 Empresas'!$C$3:$C$200,MATCH($F147,'🏢 Empresas'!$B$3:$B$200,0)),"") | H147: =IFERROR(INDEX('🏢 Empresas'!$D$3:$D$200,MATCH($F147,'🏢 Empresas'!$B$3:$B$200,0)),"") | I147: =IFERROR(INDEX('🏢 Empresas'!$E$3:$E$200,MATCH($F147,'🏢 Empresas'!$B$3:$B$200,0)),"") | J147: =IFERROR(INDEX('🏢 Empresas'!$F$3:$F$200,MATCH($F147,'🏢 Empresas'!$B$3:$B$200,0)),"") | L147: =IFERROR(INDEX('👥 Estudiantes'!$G$3:$G$200,MATCH($C147,'👥 Estudiantes'!$C$3:$C$200,0)),"") | M147: =IFERROR(INDEX('👥 Estudiantes'!$H$3:$H$200,MATCH($C147,'👥 Estudiantes'!$C$3:$C$200,0)),"") | N147: =IFERROR(INDEX('👥 Estudiantes'!$I$3:$I$200,MATCH($C147,'👥 Estudiantes'!$C$3:$C$200,0)),"") | O147: =IFERROR(INDEX('👥 Estudiantes'!$J$3:$J$200,MATCH($C147,'👥 Estudiantes'!$C$3:$C$200,0)),"")
A148: =IF($C148="","",ROW()-2) | B148: =IFERROR(INDEX('👥 Estudiantes'!$B$3:$B$200,MATCH($C148,'👥 Estudiantes'!$C$3:$C$200,0)),"") | D148: =IFERROR(INDEX('👥 Estudiantes'!$D$3:$D$200,MATCH($C148,'👥 Estudiantes'!$C$3:$C$200,0)),"") | E148: =IFERROR(INDEX('👥 Estudiantes'!$E$3:$E$200,MATCH($C148,'👥 Estudiantes'!$C$3:$C$200,0)),"") | G148: =IFERROR(INDEX('🏢 Empresas'!$C$3:$C$200,MATCH($F148,'🏢 Empresas'!$B$3:$B$200,0)),"") | H148: =IFERROR(INDEX('🏢 Empresas'!$D$3:$D$200,MATCH($F148,'🏢 Empresas'!$B$3:$B$200,0)),"") | I148: =IFERROR(INDEX('🏢 Empresas'!$E$3:$E$200,MATCH($F148,'🏢 Empresas'!$B$3:$B$200,0)),"") | J148: =IFERROR(INDEX('🏢 Empresas'!$F$3:$F$200,MATCH($F148,'🏢 Empresas'!$B$3:$B$200,0)),"") | L148: =IFERROR(INDEX('👥 Estudiantes'!$G$3:$G$200,MATCH($C148,'👥 Estudiantes'!$C$3:$C$200,0)),"") | M148: =IFERROR(INDEX('👥 Estudiantes'!$H$3:$H$200,MATCH($C148,'👥 Estudiantes'!$C$3:$C$200,0)),"") | N148: =IFERROR(INDEX('👥 Estudiantes'!$I$3:$I$200,MATCH($C148,'👥 Estudiantes'!$C$3:$C$200,0)),"") | O148: =IFERROR(INDEX('👥 Estudiantes'!$J$3:$J$200,MATCH($C148,'👥 Estudiantes'!$C$3:$C$200,0)),"")
A149: =IF($C149="","",ROW()-2) | B149: =IFERROR(INDEX('👥 Estudiantes'!$B$3:$B$200,MATCH($C149,'👥 Estudiantes'!$C$3:$C$200,0)),"") | D149: =IFERROR(INDEX('👥 Estudiantes'!$D$3:$D$200,MATCH($C149,'👥 Estudiantes'!$C$3:$C$200,0)),"") | E149: =IFERROR(INDEX('👥 Estudiantes'!$E$3:$E$200,MATCH($C149,'👥 Estudiantes'!$C$3:$C$200,0)),"") | G149: =IFERROR(INDEX('🏢 Empresas'!$C$3:$C$200,MATCH($F149,'🏢 Empresas'!$B$3:$B$200,0)),"") | H149: =IFERROR(INDEX('🏢 Empresas'!$D$3:$D$200,MATCH($F149,'🏢 Empresas'!$B$3:$B$200,0)),"") | I149: =IFERROR(INDEX('🏢 Empresas'!$E$3:$E$200,MATCH($F149,'🏢 Empresas'!$B$3:$B$200,0)),"") | J149: =IFERROR(INDEX('🏢 Empresas'!$F$3:$F$200,MATCH($F149,'🏢 Empresas'!$B$3:$B$200,0)),"") | L149: =IFERROR(INDEX('👥 Estudiantes'!$G$3:$G$200,MATCH($C149,'👥 Estudiantes'!$C$3:$C$200,0)),"") | M149: =IFERROR(INDEX('👥 Estudiantes'!$H$3:$H$200,MATCH($C149,'👥 Estudiantes'!$C$3:$C$200,0)),"") | N149: =IFERROR(INDEX('👥 Estudiantes'!$I$3:$I$200,MATCH($C149,'👥 Estudiantes'!$C$3:$C$200,0)),"") | O149: =IFERROR(INDEX('👥 Estudiantes'!$J$3:$J$200,MATCH($C149,'👥 Estudiantes'!$C$3:$C$200,0)),"")
A150: =IF($C150="","",ROW()-2) | B150: =IFERROR(INDEX('👥 Estudiantes'!$B$3:$B$200,MATCH($C150,'👥 Estudiantes'!$C$3:$C$200,0)),"") | D150: =IFERROR(INDEX('👥 Estudiantes'!$D$3:$D$200,MATCH($C150,'👥 Estudiantes'!$C$3:$C$200,0)),"") | E150: =IFERROR(INDEX('👥 Estudiantes'!$E$3:$E$200,MATCH($C150,'👥 Estudiantes'!$C$3:$C$200,0)),"") | G150: =IFERROR(INDEX('🏢 Empresas'!$C$3:$C$200,MATCH($F150,'🏢 Empresas'!$B$3:$B$200,0)),"") | H150: =IFERROR(INDEX('🏢 Empresas'!$D$3:$D$200,MATCH($F150,'🏢 Empresas'!$B$3:$B$200,0)),"") | I150: =IFERROR(INDEX('🏢 Empresas'!$E$3:$E$200,MATCH($F150,'🏢 Empresas'!$B$3:$B$200,0)),"") | J150: =IFERROR(INDEX('🏢 Empresas'!$F$3:$F$200,MATCH($F150,'🏢 Empresas'!$B$3:$B$200,0)),"") | L150: =IFERROR(INDEX('👥 Estudiantes'!$G$3:$G$200,MATCH($C150,'👥 Estudiantes'!$C$3:$C$200,0)),"") | M150: =IFERROR(INDEX('👥 Estudiantes'!$H$3:$H$200,MATCH($C150,'👥 Estudiantes'!$C$3:$C$200,0)),"") | N150: =IFERROR(INDEX('👥 Estudiantes'!$I$3:$I$200,MATCH($C150,'👥 Estudiantes'!$C$3:$C$200,0)),"") | O150: =IFERROR(INDEX('👥 Estudiantes'!$J$3:$J$200,MATCH($C150,'👥 Estudiantes'!$C$3:$C$200,0)),"")
...
